<?xml version="1.0"?>
<robot xmlns:xacro="http://www.ros.org/wiki/xacro">

    <material name="black">
        <color rgba="0.1 0.1 0.1 1.0"/>
    </material>

    <xacro:macro name="build_wheel" params="prefix x y z">

        <link name="${prefix}_wheel_link">
            <visual>
                <origin xyz="0 0 0" rpy="0 1.5708 0"/>
                <geometry>
                    <cylinder radius="0.06" length="0.04"/>
                </geometry>
                <material name="black"/>
            </visual>
            <collision>
                <origin xyz="0 0 0" rpy="0 1.5708 0"/>
                <geometry>
                    <cylinder radius="0.06" length="0.04"/>
                </geometry>
            </collision>
            <inertial>
                <origin xyz="0 0 0" rpy="0 1.5708 0"/>
                <mass value="0.5"/>
                <inertia ixx="0.0009" ixy="0.0" ixz="0.0" iyy="0.000516" iyz="0.0" izz="0.000516"/>
            </inertial>
        </link>

        <joint name="${prefix}_wheel_joint" type="continuous">
            <parent link="part_1"/>
            <child link="${prefix}_wheel_link"/>
            <origin xyz="${x} ${y} ${z}" rpy="0 0 0"/>
            <axis xyz="1 0 0"/>
            <dynamics damping="0.1" friction="0.1"/>
        </joint>

        <gazebo reference="${prefix}_wheel_link">
            <material>Gazebo/Black</material>
        </gazebo>

    </xacro:macro>
</robot>